2020-09-27 16:48:07 [Command Error] User: 'Ahnaf#4346', Message: 'sh!wrong', Error: 'ZeroDivisionError: division by zero', Traceback: Traceback (most recent call last):   File "C:\Users\HOME\AppData\Local\Programs\Python\Python38-32\lib\site-packages\lightbulb\command_handler.py", line 852, in process_commands_for_event     await self._invoke_command(command, context, positional_args, keyword_arg)   File "C:\Users\HOME\AppData\Local\Programs\Python\Python38-32\lib\site-packages\lightbulb\command_handler.py", line 788, in _invoke_command     await command.invoke(context)   File "C:\Users\HOME\AppData\Local\Programs\Python\Python38-32\lib\site-packages\lightbulb\commands.py", line 495, in invoke     return await self._callback(context, *new_args, **kwargs)   File "F:\Ahnaf's Folder\Shikamaru Bot\shikamaru\bot.py", line 20, in wrong     await ctx.reply(1/0) lightbulb.errors.CommandInvocationError: ZeroDivisionError: division by zero 
2020-09-27 17:05:39 [Command Error] User: 'Forbidden#0001', Message: 'sh!source', Error: 'source', Traceback: Traceback (most recent call last):   File "C:\Users\HOME\AppData\Local\Programs\Python\Python38-32\lib\site-packages\lightbulb\command_handler.py", line 813, in process_commands_for_event     command = self._validate_command_exists(invoked_with)   File "C:\Users\HOME\AppData\Local\Programs\Python\Python38-32\lib\site-packages\lightbulb\command_handler.py", line 730, in _validate_command_exists     raise errors.CommandNotFound(invoked_with) lightbulb.errors.CommandNotFound: source 
2020-09-27 17:05:47 [Command Error] User: 'Forbidden#0001', Message: 'sh!github', Error: 'github', Traceback: Traceback (most recent call last):   File "C:\Users\HOME\AppData\Local\Programs\Python\Python38-32\lib\site-packages\lightbulb\command_handler.py", line 813, in process_commands_for_event     command = self._validate_command_exists(invoked_with)   File "C:\Users\HOME\AppData\Local\Programs\Python\Python38-32\lib\site-packages\lightbulb\command_handler.py", line 730, in _validate_command_exists     raise errors.CommandNotFound(invoked_with) lightbulb.errors.CommandNotFound: github 
2020-09-27 17:05:49 [Command Error] User: 'Forbidden#0001', Message: 'sh!gitlab', Error: 'gitlab', Traceback: Traceback (most recent call last):   File "C:\Users\HOME\AppData\Local\Programs\Python\Python38-32\lib\site-packages\lightbulb\command_handler.py", line 813, in process_commands_for_event     command = self._validate_command_exists(invoked_with)   File "C:\Users\HOME\AppData\Local\Programs\Python\Python38-32\lib\site-packages\lightbulb\command_handler.py", line 730, in _validate_command_exists     raise errors.CommandNotFound(invoked_with) lightbulb.errors.CommandNotFound: gitlab 
2020-09-27 17:40:37 [Command Error] User: 'Ahnaf#4346', Message: 'sh!rtfm zenora guild', Error: 'AttributeError: 'RTFM' object has no attribute 'docs_links'', Traceback: Traceback (most recent call last):   File "C:\Users\HOME\AppData\Local\Programs\Python\Python38-32\lib\site-packages\lightbulb\command_handler.py", line 852, in process_commands_for_event     await self._invoke_command(command, context, positional_args, keyword_arg)   File "C:\Users\HOME\AppData\Local\Programs\Python\Python38-32\lib\site-packages\lightbulb\command_handler.py", line 784, in _invoke_command     await command.invoke(context, *args, **kwarg)   File "C:\Users\HOME\AppData\Local\Programs\Python\Python38-32\lib\site-packages\lightbulb\commands.py", line 88, in invoke     return await self._callback(instance, context, *new_args, **kwargs)   File "F:\Ahnaf's Folder\Shikamaru Bot\shikamaru\plugins\rtfm.py", line 159, in rtfm     await self.do_rtfm(ctx, module, key, obj)   File "F:\Ahnaf's Folder\Shikamaru Bot\shikamaru\plugins\rtfm.py", line 125, in do_rtfm     if not site in self.docs_links: lightbulb.errors.CommandInvocationError: AttributeError: 'RTFM' object has no attribute 'docs_links' 
2020-09-27 17:42:15 [Command Error] User: 'Ahnaf#4346', Message: 'sh!rtfm zenora guild', Error: 'AttributeError: 'Context' object has no attribute 'trigger_typing'', Traceback: Traceback (most recent call last):   File "C:\Users\HOME\AppData\Local\Programs\Python\Python38-32\lib\site-packages\lightbulb\command_handler.py", line 852, in process_commands_for_event     await self._invoke_command(command, context, positional_args, keyword_arg)   File "C:\Users\HOME\AppData\Local\Programs\Python\Python38-32\lib\site-packages\lightbulb\command_handler.py", line 784, in _invoke_command     await command.invoke(context, *args, **kwarg)   File "C:\Users\HOME\AppData\Local\Programs\Python\Python38-32\lib\site-packages\lightbulb\commands.py", line 88, in invoke     return await self._callback(instance, context, *new_args, **kwargs)   File "F:\Ahnaf's Folder\Shikamaru Bot\shikamaru\plugins\rtfm.py", line 159, in rtfm     await self.do_rtfm(ctx, module, key, obj)   File "F:\Ahnaf's Folder\Shikamaru Bot\shikamaru\plugins\rtfm.py", line 137, in do_rtfm     await ctx.trigger_typing() lightbulb.errors.CommandInvocationError: AttributeError: 'Context' object has no attribute 'trigger_typing' 
2020-09-27 17:48:54 [Command Error] User: 'Ahnaf#4346', Message: 'sh!rtfm zenora guild', Error: 'NameError: name 'discord' is not defined', Traceback: Traceback (most recent call last):   File "C:\Users\HOME\AppData\Local\Programs\Python\Python38-32\lib\site-packages\lightbulb\command_handler.py", line 852, in process_commands_for_event     await self._invoke_command(command, context, positional_args, keyword_arg)   File "C:\Users\HOME\AppData\Local\Programs\Python\Python38-32\lib\site-packages\lightbulb\command_handler.py", line 784, in _invoke_command     await command.invoke(context, *args, **kwarg)   File "C:\Users\HOME\AppData\Local\Programs\Python\Python38-32\lib\site-packages\lightbulb\commands.py", line 88, in invoke     return await self._callback(instance, context, *new_args, **kwargs)   File "F:\Ahnaf's Folder\Shikamaru Bot\shikamaru\plugins\rtfm.py", line 159, in rtfm     await self.do_rtfm(ctx, module, key, obj)   File "F:\Ahnaf's Folder\Shikamaru Bot\shikamaru\plugins\rtfm.py", line 147, in do_rtfm     e = discord.Embed(colour=discord.Color.blue(), lightbulb.errors.CommandInvocationError: NameError: name 'discord' is not defined 
2020-09-27 18:06:43 [Command Error] User: 'Ahnaf#4346', Message: 'sh!code
```py
does this work?
', Error: 'AttributeError: 'Message' object has no attribute 'channel'', Traceback: Traceback (most recent call last):   File "C:\Users\HOME\AppData\Local\Programs\Python\Python38-32\lib\site-packages\lightbulb\command_handler.py", line 852, in process_commands_for_event     await self._invoke_command(command, context, positional_args, keyword_arg)   File "C:\Users\HOME\AppData\Local\Programs\Python\Python38-32\lib\site-packages\lightbulb\command_handler.py", line 788, in _invoke_command     await command.invoke(context)   File "C:\Users\HOME\AppData\Local\Programs\Python\Python38-32\lib\site-packages\lightbulb\commands.py", line 88, in invoke     return await self._callback(instance, context, *new_args, **kwargs)   File "F:\Ahnaf's Folder\Shikamaru Bot\shikamaru\plugins\owner.py", line 23, in code     channel = ctx.message.channel lightbulb.errors.CommandInvocationError: AttributeError: 'Message' object has no attribute 'channel' 
2020-09-27 18:09:06 [Command Error] User: 'Ahnaf#4346', Message: 'sh!code
```py
does this work?
', Error: 'AttributeError: 'Bot' object has no attribute 'get_guild_channel'', Traceback: Traceback (most recent call last):   File "C:\Users\HOME\AppData\Local\Programs\Python\Python38-32\lib\site-packages\lightbulb\command_handler.py", line 852, in process_commands_for_event     await self._invoke_command(command, context, positional_args, keyword_arg)   File "C:\Users\HOME\AppData\Local\Programs\Python\Python38-32\lib\site-packages\lightbulb\command_handler.py", line 788, in _invoke_command     await command.invoke(context)   File "C:\Users\HOME\AppData\Local\Programs\Python\Python38-32\lib\site-packages\lightbulb\commands.py", line 88, in invoke     return await self._callback(instance, context, *new_args, **kwargs)   File "F:\Ahnaf's Folder\Shikamaru Bot\shikamaru\plugins\owner.py", line 23, in code     channel = self.bot.get_guild_channel(ctx.message.channel_id) lightbulb.errors.CommandInvocationError: AttributeError: 'Bot' object has no attribute 'get_guild_channel' 
2020-09-27 18:10:29 [Command Error] User: 'Ahnaf#4346', Message: 'sh!code
```py
does this work?
', Error: 'AttributeError: 'GuildTextChannel' object has no attribute 'trigger_typing'', Traceback: Traceback (most recent call last):   File "C:\Users\HOME\AppData\Local\Programs\Python\Python38-32\lib\site-packages\lightbulb\command_handler.py", line 852, in process_commands_for_event     await self._invoke_command(command, context, positional_args, keyword_arg)   File "C:\Users\HOME\AppData\Local\Programs\Python\Python38-32\lib\site-packages\lightbulb\command_handler.py", line 788, in _invoke_command     await command.invoke(context)   File "C:\Users\HOME\AppData\Local\Programs\Python\Python38-32\lib\site-packages\lightbulb\commands.py", line 88, in invoke     return await self._callback(instance, context, *new_args, **kwargs)   File "F:\Ahnaf's Folder\Shikamaru Bot\shikamaru\plugins\owner.py", line 25, in code     await channel.trigger_typing() lightbulb.errors.CommandInvocationError: AttributeError: 'GuildTextChannel' object has no attribute 'trigger_typing' 
2020-09-27 18:14:58 [Command Error] User: 'Ahnaf#4346', Message: 'sh!code
```py
return "fuck you', Error: 'BadRequestError: Bad Request 400: 'Cannot send an empty message' for https://discord.com/api/v6/channels/574921092926537729/messages', Traceback: Traceback (most recent call last):   File "C:\Users\HOME\AppData\Local\Programs\Python\Python38-32\lib\site-packages\lightbulb\command_handler.py", line 852, in process_commands_for_event     await self._invoke_command(command, context, positional_args, keyword_arg)   File "C:\Users\HOME\AppData\Local\Programs\Python\Python38-32\lib\site-packages\lightbulb\command_handler.py", line 788, in _invoke_command     await command.invoke(context)   File "C:\Users\HOME\AppData\Local\Programs\Python\Python38-32\lib\site-packages\lightbulb\commands.py", line 88, in invoke     return await self._callback(instance, context, *new_args, **kwargs)   File "F:\Ahnaf's Folder\Shikamaru Bot\shikamaru\plugins\owner.py", line 76, in code     await ctx.reply()   File "C:\Users\HOME\AppData\Local\Programs\Python\Python38-32\lib\site-packages\lightbulb\context.py", line 193, in reply     return await self.message.reply(*args, **kwargs)   File "C:\Users\HOME\AppData\Local\Programs\Python\Python38-32\lib\site-packages\hikari\messages.py", line 649, in reply     return await self.app.rest.create_message(   File "C:\Users\HOME\AppData\Local\Programs\Python\Python38-32\lib\site-packages\hikari\impl\rest.py", line 1053, in create_message     raw_response = await self._request(route, json=body)   File "C:\Users\HOME\AppData\Local\Programs\Python\Python38-32\lib\site-packages\hikari\impl\rest.py", line 600, in _request     await self._handle_error_response(response)   File "C:\Users\HOME\AppData\Local\Programs\Python\Python38-32\lib\site-packages\hikari\impl\rest.py", line 621, in _handle_error_response     raise await net.generate_error_response(response) lightbulb.errors.CommandInvocationError: BadRequestError: Bad Request 400: 'Cannot send an empty message' for https://discord.com/api/v6/channels/574921092926537729/messages 
